Workbook

Sheet 00_Dashboard
A1: DASHBOARD - ANALISIS NAVEGACION SOCIAL ROBOT AGRICOLA
A3: Estudio de gemelo digital Unity-MATLAB | 184 corridas | 5 métodos × 4 escenarios × 10 corridas
A5: RANKING FINAL (TOPSIS)
A6: Pos. | B6: Método | C6: CC sin pen. | D6: CC con pen. | E6: Notas
A7: 1 | B7: M4 | C7: 0.80388393 | D7: 0.80090736 | E7: GANADOR: campos sociales continuos + supervisor (PROPUESTO)
A8: 2 | B8: M3 | C8: 0.80332675 | D8: 0.79634794 | E8: Campos sociales sin supervisor (close 2nd, 100% éxito)
A9: 3 | B9: M0 | C9: 0.64880061 | D9: 0.66329255 | E9: NavMesh puro - intermedio
A10: 4 | B10: M2 | C10: 0.52598109 | D10: 0.22683418 | E10: Supervisor binario distancia+orientación - bloqueo en E4
A11: 5 | B11: M1 | C11: 0.15193459 | D11: 0.076484563 | E11: Supervisor binario distancia - bloqueo severo en E4
A13: HIPOTESIS Y RESULTADOS CLAVE
A14: Hipótesis | B14: Resultado | C14: Estadístico | D14: p-valor | E14: Conclusión
A15: H1: M0 invade zona íntima | B15: Confirmada | C15: KW H=0.23 | D15: 1.24e-01 | E15: M0 muestra T_intimo > 0 frecuentemente
A16: H2: M1/M2 mejoran d* en E2/E3 | B16: Parcial | C16: MW pareado | D16: <0.05 | E16: Mejora local pero genera bloqueos en E4
A17: H3: M3 ofrece d* mayor | B17: Confirmada | C17: KW H=115.30 | D17: 5.39e-24 | E17: M3 d*=1.004m > otros
A18: H4: M4 mejora suavidad | B18: CONFIRMADA FUERTE | C18: KW H=164.97 | D18: 1.25e-34 | E18: M4 σ_v=0.195 < M3=0.243
A19: H5: M4 reduce N_stop | B19: Confirmada vs M1/M2 | C19: KW H=124.19 | D19: 1.08e-31 | E19: M4 N_stop=0.2 << M1=9.9
A20: H6: M4 mejora η_s en E4 | B20: CONFIRMADA FUERTE | C20: Chi²=26.09 V=0.361 | D20: 3.04e-05 | E20: Fisher M4vsM1: p=7.14e-04
A22: METRICAS CLAVE POR METODO (medias)
A23: Método | B23: d* (m) | C23: T_pers (s) | D23: N_stop | E23: σ_v (m/s) | F23: a_max (m/s²) | G23: η_s (%) | H23: Tasa éxito
A24: M0 | B24: 0.56275 | C24: 25.365243 | D24: 0.2 | E24: 0.066285825 | F24: 12.430272 | G24: 100 | H24: 40/40
A25: M1 | B25: 0.75042813 | C25: 20.322525 | D25: 9.90625 | E25: 0.37831588 | F25: 11.275328 | G25: 80 | H25: 32/40
A26: M2 | B26: 0.74530937 | C26: 12.428241 | D26: 3.21875 | E26: 0.41006278 | F26: 11.010691 | G26: 80 | H26: 32/40
A27: M3 | B27: 1.0037675 | C27: 7.574015 | D27: 0.025 | E27: 0.24278337 | F27: 9.370985 | G27: 100 | H27: 40/40
A28: M4 | B28: 0.8458825 | C28: 11.72021 | D28: 0.2 | E28: 0.1951916 | F28: 10.283765 | G28: 100 | H28: 40/40
A31: VISUALIZACION
A55: Método | B55: CC sin pen. | C55: CC con pen.
A56: M0 | B56: 0.64880061 | C56: 0.66329255
A57: M1 | B57: 0.15193459 | C57: 0.076484563
A58: M2 | B58: 0.52598109 | C58: 0.22683418
A59: M3 | B59: 0.80332675 | C59: 0.79634794
A60: M4 | B60: 0.80388393 | C60: 0.80090736
A63: Método | B63: η_s (%)
A64: M0 | B64: 100
A65: M1 | B65: 80
A66: M2 | B66: 80
A67: M3 | B67: 100
A68: M4 | B68: 100

Sheet 01_Datos_brutos
A1: MASTER LOG - 184 corridas registradas
A3: Metodo | B3: Escenario | C3: RunID | D3: Timestamp | E3: TiempoTotal_s | F3: LongitudTrayectoria_m | G3: DistMin_m | H3: DistMedia_m | I3: DistMediana_m | J3: DistP05_m | K3: DistIQR_m | L3: VelMedia_mps | M3: VelMediana_mps | N3: VelMax_mps | O3: VelStd_mps | P3: AccMax_mps2 | Q3: AccRMS_mps2 | R3: TiempoSocial_s | S3: TiempoPersonal_s | T3: TiempoIntima_s | U3: TiempoStop_s | V3: NumeroStops | W3: EficienciaTrayectoria | X3: PacketsValid | Y3: PacketsInvalid | Z3: PacketsOutOfOrder
A4: M0 | B4: E1 | C4: 1 | D4: 2026-05-02 18:42:04 | E4: 93.8764 | F4: 93.514398 | G4: 0.4698 | H4: 9.828845 | I4: 12 | J4: 0.97659 | K4: 3.3519 | L4: 0.999889 | M4: 1 | N4: 2.8287 | O4: 0.103283 | P4: 24.4818 | Q4: 1.239582 | R4: 12.3794 | S4: 5.9441 | T4: 0 | U4: 0.177 | V4: 1 | W4: 0.996144 | X4: 456 | Y4: 0 | Z4: 0
A5: M0 | B5: E1 | C5: 2 | D5: 2026-05-02 18:44:45 | E5: 94.3218 | F5: 93.841702 | G5: 0.4535 | H5: 9.817498 | I5: 12 | J5: 1.0202 | K5: 3.3917 | L5: 0.997203 | M5: 1 | N5: 1.8706 | O5: 0.07072 | P5: 12.36 | Q5: 0.66876 | R5: 12.5284 | S5: 5.999 | T5: 0 | U5: 0 | V5: 0 | W5: 0.99491 | X5: 386 | Y5: 0 | Z5: 0
A6: M0 | B6: E1 | C6: 3 | D6: 2026-05-02 18:47:34 | E6: 93.7374 | F6: 93.446294 | G6: 0.5528 | H6: 10.025686 | I6: 12 | J6: 1.66174 | K6: 2.773075 | L6: 0.998089 | M6: 1 | N6: 1.5619 | O6: 0.05435 | P6: 5.9371 | Q6: 0.417735 | R6: 10.1551 | S6: 3.1517 | T6: 0 | U6: 0 | V6: 0 | W6: 0.996894 | X6: 329 | Y6: 0 | Z6: 0
A7: M0 | B7: E1 | C7: 4 | D7: 2026-05-02 18:50:31 | E7: 94.2812 | F7: 93.979802 | G7: 0.5881 | H7: 10.200167 | I7: 12 | J7: 1.8864 | K7: 1.919075 | L7: 0.998187 | M7: 1 | N7: 1.7313 | O7: 0.056806 | P7: 9.7656 | Q7: 0.592365 | R7: 9.7378 | S7: 2.2677 | T7: 0 | U7: 0 | V7: 0 | W7: 0.996803 | X7: 375 | Y7: 0 | Z7: 0
A8: M0 | B8: E1 | C8: 5 | D8: 2026-05-02 18:52:56 | E8: 93.8015 | F8: 93.456895 | G8: 0.4665 | H8: 10.093968 | I8: 12 | J8: 1.533585 | K8: 1.901425 | L8: 0.996509 | M8: 1 | N8: 1.4352 | O8: 0.059464 | P8: 4.9602 | Q8: 0.368643 | R8: 11.1113 | S8: 4.7791 | T8: 0 | U8: 0.2074 | V8: 1 | W8: 0.996326 | X8: 383 | Y8: 0 | Z8: 0
A9: M0 | B9: E1 | C9: 6 | D9: 2026-05-02 18:55:43 | E9: 93.9657 | F9: 93.688798 | G9: 0.5411 | H9: 9.934626 | I9: 12 | J9: 1.496775 | K9: 3.126975 | L9: 1.000198 | M9: 1 | N9: 2.2234 | O9: 0.084411 | P9: 18.9195 | Q9: 1.074463 | R9: 10.1683 | S9: 3.7966 | T9: 0 | U9: 0 | V9: 0 | W9: 0.997053 | X9: 337 | Y9: 0 | Z9: 0
A10: M0 | B10: E1 | C10: 7 | D10: 2026-05-02 18:59:48 | E10: 94.3137 | F10: 93.8785 | G10: 1.0767 | H10: 10.155294 | I10: 12 | J10: 2.0581 | K10: 2.3965 | L10: 0.9963 | M10: 1 | N10: 1.3609 | O10: 0.055283 | P10: 4.9509 | Q10: 0.330644 | R10: 9.141 | S10: 1.6259 | T10: 0 | U10: 0 | V10: 0 | W10: 0.995386 | X10: 386 | Y10: 0 | Z10: 0
A11: M0 | B11: E1 | C11: 8 | D11: 2026-05-02 19:02:18 | E11: 94.1188 | F11: 93.755398 | G11: 0.4787 | H11: 9.999804 | I11: 12 | J11: 1.474915 | K11: 2.8261 | L11: 0.998934 | M11: 1 | N11: 1.9582 | O11: 0.069397 | P11: 10.771 | Q11: 0.649968 | R11: 10.3355 | S11: 4.0727 | T11: 0 | U11: 0 | V11: 0 | W11: 0.996139 | X11: 333 | Y11: 0 | Z11: 0
A12: M0 | B12: E1 | C12: 9 | D12: 2026-05-02 19:05:28 | E12: 94.184 | F12: 93.752601 | G12: 0.5163 | H12: 9.949407 | I12: 12 | J12: 1.486455 | K12: 3.02435 | L12: 0.995003 | M12: 1 | N12: 1 | O12: 0.053669 | P12: 3.8839 | Q12: 0.26946 | R12: 10.962 | S12: 4.0436 | T12: 0 | U12: 0.1979 | V12: 1 | W12: 0.99542 | X12: 399 | Y12: 0 | Z12: 0
A13: M0 | B13: E1 | C13: 10 | D13: 2026-05-02 19:07:56 | E13: 94.3939 | F13: 94.087905 | G13: 0.4599 | H13: 9.846503 | I13: 12 | J13: 1.10914 | K13: 3.3983 | L13: 0.999715 | M13: 1 | N13: 2.025 | O13: 0.072487 | P13: 17.5034 | Q13: 1.025078 | R13: 11.5942 | S13: 4.968 | T13: 0 | U13: 0 | V13: 0 | W13: 0.996758 | X13: 332 | Y13: 0 | Z13: 0
A14: M0 | B14: E2 | C14: 1 | D14: 2026-05-02 21:32:53 | E14: 93.8346 | F14: 93.439402 | G14: 0.6443 | H14: 3.405486 | I14: 2.609 | J14: 0.806535 | K14: 2.412925 | L14: 0.997636 | M14: 1 | N14: 2.0658 | O14: 0.063289 | P14: 12.8192 | Q14: 0.59971 | R14: 69.3382 | S14: 18.5842 | T14: 0 | U14: 0 | V14: 0 | W14: 0.995788 | X14: 677 | Y14: 0 | Z14: 0
A15: M0 | B15: E2 | C15: 2 | D15: 2026-05-02 21:35:24 | E15: 93.6964 | F15: 93.319539 | G15: 0.641 | H15: 3.377045 | I15: 1.4202 | J15: 0.8048 | K15: 4.18555 | L15: 0.997238 | M15: 1 | N15: 1.8856 | O15: 0.05917 | P15: 10.7069 | Q15: 0.538279 | R15: 60.7654 | S15: 39.6072 | T15: 0 | U15: 0 | V15: 0 | W15: 0.995978 | X15: 669 | Y15: 0 | Z15: 0
... A187: M4 | B187: E4 | C187: 10 | D187: 2026-05-03 19:06:31 | E187: 151.2995 | F187: 96.522978 | G187: 0.7533 | H187: 2.85934 | I187: 1.9791 | J187: 0.95675 | K187: 1.90575 | L187: 0.640803 | M187: 0.6075 | N187: 2.3151 | O187: 0.19091 | P187: 14.7836 | Q187: 0.757091 | R187: 124.4774 | S187: 15.5454 | T187: 0 | U187: 0 | V187: 0 | W187: 0.63796 | X187: 996 | Y187: 0 | Z187: 0

Sheet 02_Descriptiva
A1: ESTADISTICA DESCRIPTIVA POR METODO Y METRICA (con fórmulas)
A3: Notas:
A4: - Las fórmulas hacen referencia a la hoja 01_Datos_brutos. Modifique los datos brutos y todo se recalcula.
A5: - Azul = inputs / parámetros; Negro = fórmulas; Verde = referencias entre hojas.
A7: Metodo | B7: Metrica | C7: n | D7: Media | E7: SD | F7: CV | G7: Min | H7: Q25 | I7: Mediana | J7: Q75 | K7: Max | L7: IQR
A8: M0 | B8: DistMin_m | C8: =COUNTIFS('01_Datos_brutos'!A4:A187,"M0") | D8: =AVERAGEIFS('01_Datos_brutos'!G4:G187,'01_Datos_brutos'!A4:A187,"M0") | E8: =STDEV(IF('01_Datos_brutos'!A4:A187="M0",'01_Datos_brutos'!G4:G187)) | F8: =IFERROR(E8/D8,"") | G8: =MINIFS('01_Datos_brutos'!G4:G187,'01_Datos_brutos'!A4:A187,"M0") | H8: =PERCENTILE(IF('01_Datos_brutos'!A4:A187="M0",'01_Datos_brutos'!G4:G187),0.25) | I8: =PERCENTILE(IF('01_Datos_brutos'!A4:A187="M0",'01_Datos_brutos'!G4:G187),0.5) | J8: =PERCENTILE(IF('01_Datos_brutos'!A4:A187="M0",'01_Datos_brutos'!G4:G187),0.75) | K8: =MAXIFS('01_Datos_brutos'!G4:G187,'01_Datos_brutos'!A4:A187,"M0") | L8: =J8-H8
A9: M0 | B9: DistMedia_m | C9: =COUNTIFS('01_Datos_brutos'!A4:A187,"M0") | D9: =AVERAGEIFS('01_Datos_brutos'!H4:H187,'01_Datos_brutos'!A4:A187,"M0") | E9: =STDEV(IF('01_Datos_brutos'!A4:A187="M0",'01_Datos_brutos'!H4:H187)) | F9: =IFERROR(E9/D9,"") | G9: =MINIFS('01_Datos_brutos'!H4:H187,'01_Datos_brutos'!A4:A187,"M0") | H9: =PERCENTILE(IF('01_Datos_brutos'!A4:A187="M0",'01_Datos_brutos'!H4:H187),0.25) | I9: =PERCENTILE(IF('01_Datos_brutos'!A4:A187="M0",'01_Datos_brutos'!H4:H187),0.5) | J9: =PERCENTILE(IF('01_Datos_brutos'!A4:A187="M0",'01_Datos_brutos'!H4:H187),0.75) | K9: =MAXIFS('01_Datos_brutos'!H4:H187,'01_Datos_brutos'!A4:A187,"M0") | L9: =J9-H9
A10: M0 | B10: DistP05_m | C10: =COUNTIFS('01_Datos_brutos'!A4:A187,"M0") | D10: =AVERAGEIFS('01_Datos_brutos'!J4:J187,'01_Datos_brutos'!A4:A187,"M0") | E10: =STDEV(IF('01_Datos_brutos'!A4:A187="M0",'01_Datos_brutos'!J4:J187)) | F10: =IFERROR(E10/D10,"") | G10: =MINIFS('01_Datos_brutos'!J4:J187,'01_Datos_brutos'!A4:A187,"M0") | H10: =PERCENTILE(IF('01_Datos_brutos'!A4:A187="M0",'01_Datos_brutos'!J4:J187),0.25) | I10: =PERCENTILE(IF('01_Datos_brutos'!A4:A187="M0",'01_Datos_brutos'!J4:J187),0.5) | J10: =PERCENTILE(IF('01_Datos_brutos'!A4:A187="M0",'01_Datos_brutos'!J4:J187),0.75) | K10: =MAXIFS('01_Datos_brutos'!J4:J187,'01_Datos_brutos'!A4:A187,"M0") | L10: =J10-H10
A11: M0 | B11: TiempoPersonal_s | C11: =COUNTIFS('01_Datos_brutos'!A4:A187,"M0") | D11: =AVERAGEIFS('01_Datos_brutos'!S4:S187,'01_Datos_brutos'!A4:A187,"M0") | E11: =STDEV(IF('01_Datos_brutos'!A4:A187="M0",'01_Datos_brutos'!S4:S187)) | F11: =IFERROR(E11/D11,"") | G11: =MINIFS('01_Datos_brutos'!S4:S187,'01_Datos_brutos'!A4:A187,"M0") | H11: =PERCENTILE(IF('01_Datos_brutos'!A4:A187="M0",'01_Datos_brutos'!S4:S187),0.25) | I11: =PERCENTILE(IF('01_Datos_brutos'!A4:A187="M0",'01_Datos_brutos'!S4:S187),0.5) | J11: =PERCENTILE(IF('01_Datos_brutos'!A4:A187="M0",'01_Datos_brutos'!S4:S187),0.75) | K11: =MAXIFS('01_Datos_brutos'!S4:S187,'01_Datos_brutos'!A4:A187,"M0") | L11: =J11-H11
A12: M0 | B12: TiempoIntima_s | C12: =COUNTIFS('01_Datos_brutos'!A4:A187,"M0") | D12: =AVERAGEIFS('01_Datos_brutos'!T4:T187,'01_Datos_brutos'!A4:A187,"M0") | E12: =STDEV(IF('01_Datos_brutos'!A4:A187="M0",'01_Datos_brutos'!T4:T187)) | F12: =IFERROR(E12/D12,"") | G12: =MINIFS('01_Datos_brutos'!T4:T187,'01_Datos_brutos'!A4:A187,"M0") | H12: =PERCENTILE(IF('01_Datos_brutos'!A4:A187="M0",'01_Datos_brutos'!T4:T187),0.25) | I12: =PERCENTILE(IF('01_Datos_brutos'!A4:A187="M0",'01_Datos_brutos'!T4:T187),0.5) | J12: =PERCENTILE(IF('01_Datos_brutos'!A4:A187="M0",'01_Datos_brutos'!T4:T187),0.75) | K12: =MAXIFS('01_Datos_brutos'!T4:T187,'01_Datos_brutos'!A4:A187,"M0") | L12: =J12-H12
A13: M0 | B13: TiempoTotal_s | C13: =COUNTIFS('01_Datos_brutos'!A4:A187,"M0") | D13: =AVERAGEIFS('01_Datos_brutos'!E4:E187,'01_Datos_brutos'!A4:A187,"M0") | E13: =STDEV(IF('01_Datos_brutos'!A4:A187="M0",'01_Datos_brutos'!E4:E187)) | F13: =IFERROR(E13/D13,"") | G13: =MINIFS('01_Datos_brutos'!E4:E187,'01_Datos_brutos'!A4:A187,"M0") | H13: =PERCENTILE(IF('01_Datos_brutos'!A4:A187="M0",'01_Datos_brutos'!E4:E187),0.25) | I13: =PERCENTILE(IF('01_Datos_brutos'!A4:A187="M0",'01_Datos_brutos'!E4:E187),0.5) | J13: =PERCENTILE(IF('01_Datos_brutos'!A4:A187="M0",'01_Datos_brutos'!E4:E187),0.75) | K13: =MAXIFS('01_Datos_brutos'!E4:E187,'01_Datos_brutos'!A4:A187,"M0") | L13: =J13-H13
A14: M0 | B14: LongitudTrayectoria_m | C14: =COUNTIFS('01_Datos_brutos'!A4:A187,"M0") | D14: =AVERAGEIFS('01_Datos_brutos'!F4:F187,'01_Datos_brutos'!A4:A187,"M0") | E14: =STDEV(IF('01_Datos_brutos'!A4:A187="M0",'01_Datos_brutos'!F4:F187)) | F14: =IFERROR(E14/D14,"") | G14: =MINIFS('01_Datos_brutos'!F4:F187,'01_Datos_brutos'!A4:A187,"M0") | H14: =PERCENTILE(IF('01_Datos_brutos'!A4:A187="M0",'01_Datos_brutos'!F4:F187),0.25) | I14: =PERCENTILE(IF('01_Datos_brutos'!A4:A187="M0",'01_Datos_brutos'!F4:F187),0.5) | J14: =PERCENTILE(IF('01_Datos_brutos'!A4:A187="M0",'01_Datos_brutos'!F4:F187),0.75) | K14: =MAXIFS('01_Datos_brutos'!F4:F187,'01_Datos_brutos'!A4:A187,"M0") | L14: =J14-H14
A15: M0 | B15: VelMedia_mps | C15: =COUNTIFS('01_Datos_brutos'!A4:A187,"M0") | D15: =AVERAGEIFS('01_Datos_brutos'!L4:L187,'01_Datos_brutos'!A4:A187,"M0") | E15: =STDEV(IF('01_Datos_brutos'!A4:A187="M0",'01_Datos_brutos'!L4:L187)) | F15: =IFERROR(E15/D15,"") | G15: =MINIFS('01_Datos_brutos'!L4:L187,'01_Datos_brutos'!A4:A187,"M0") | H15: =PERCENTILE(IF('01_Datos_brutos'!A4:A187="M0",'01_Datos_brutos'!L4:L187),0.25) | I15: =PERCENTILE(IF('01_Datos_brutos'!A4:A187="M0",'01_Datos_brutos'!L4:L187),0.5) | J15: =PERCENTILE(IF('01_Datos_brutos'!A4:A187="M0",'01_Datos_brutos'!L4:L187),0.75) | K15: =MAXIFS('01_Datos_brutos'!L4:L187,'01_Datos_brutos'!A4:A187,"M0") | L15: =J15-H15
A16: M0 | B16: VelMax_mps | C16: =COUNTIFS('01_Datos_brutos'!A4:A187,"M0") | D16: =AVERAGEIFS('01_Datos_brutos'!N4:N187,'01_Datos_brutos'!A4:A187,"M0") | E16: =STDEV(IF('01_Datos_brutos'!A4:A187="M0",'01_Datos_brutos'!N4:N187)) | F16: =IFERROR(E16/D16,"") | G16: =MINIFS('01_Datos_brutos'!N4:N187,'01_Datos_brutos'!A4:A187,"M0") | H16: =PERCENTILE(IF('01_Datos_brutos'!A4:A187="M0",'01_Datos_brutos'!N4:N187),0.25) | I16: =PERCENTILE(IF('01_Datos_brutos'!A4:A187="M0",'01_Datos_brutos'!N4:N187),0.5) | J16: =PERCENTILE(IF('01_Datos_brutos'!A4:A187="M0",'01_Datos_brutos'!N4:N187),0.75) | K16: =MAXIFS('01_Datos_brutos'!N4:N187,'01_Datos_brutos'!A4:A187,"M0") | L16: =J16-H16
A17: M0 | B17: VelStd_mps | C17: =COUNTIFS('01_Datos_brutos'!A4:A187,"M0") | D17: =AVERAGEIFS('01_Datos_brutos'!O4:O187,'01_Datos_brutos'!A4:A187,"M0") | E17: =STDEV(IF('01_Datos_brutos'!A4:A187="M0",'01_Datos_brutos'!O4:O187)) | F17: =IFERROR(E17/D17,"") | G17: =MINIFS('01_Datos_brutos'!O4:O187,'01_Datos_brutos'!A4:A187,"M0") | H17: =PERCENTILE(IF('01_Datos_brutos'!A4:A187="M0",'01_Datos_brutos'!O4:O187),0.25) | I17: =PERCENTILE(IF('01_Datos_brutos'!A4:A187="M0",'01_Datos_brutos'!O4:O187),0.5) | J17: =PERCENTILE(IF('01_Datos_brutos'!A4:A187="M0",'01_Datos_brutos'!O4:O187),0.75) | K17: =MAXIFS('01_Datos_brutos'!O4:O187,'01_Datos_brutos'!A4:A187,"M0") | L17: =J17-H17
A18: M0 | B18: AccMax_mps2 | C18: =COUNTIFS('01_Datos_brutos'!A4:A187,"M0") | D18: =AVERAGEIFS('01_Datos_brutos'!P4:P187,'01_Datos_brutos'!A4:A187,"M0") | E18: =STDEV(IF('01_Datos_brutos'!A4:A187="M0",'01_Datos_brutos'!P4:P187)) | F18: =IFERROR(E18/D18,"") | G18: =MINIFS('01_Datos_brutos'!P4:P187,'01_Datos_brutos'!A4:A187,"M0") | H18: =PERCENTILE(IF('01_Datos_brutos'!A4:A187="M0",'01_Datos_brutos'!P4:P187),0.25) | I18: =PERCENTILE(IF('01_Datos_brutos'!A4:A187="M0",'01_Datos_brutos'!P4:P187),0.5) | J18: =PERCENTILE(IF('01_Datos_brutos'!A4:A187="M0",'01_Datos_brutos'!P4:P187),0.75) | K18: =MAXIFS('01_Datos_brutos'!P4:P187,'01_Datos_brutos'!A4:A187,"M0") | L18: =J18-H18
A19: M0 | B19: AccRMS_mps2 | C19: =COUNTIFS('01_Datos_brutos'!A4:A187,"M0") | D19: =AVERAGEIFS('01_Datos_brutos'!Q4:Q187,'01_Datos_brutos'!A4:A187,"M0") | E19: =STDEV(IF('01_Datos_brutos'!A4:A187="M0",'01_Datos_brutos'!Q4:Q187)) | F19: =IFERROR(E19/D19,"") | G19: =MINIFS('01_Datos_brutos'!Q4:Q187,'01_Datos_brutos'!A4:A187,"M0") | H19: =PERCENTILE(IF('01_Datos_brutos'!A4:A187="M0",'01_Datos_brutos'!Q4:Q187),0.25) | I19: =PERCENTILE(IF('01_Datos_brutos'!A4:A187="M0",'01_Datos_brutos'!Q4:Q187),0.5) | J19: =PERCENTILE(IF('01_Datos_brutos'!A4:A187="M0",'01_Datos_brutos'!Q4:Q187),0.75) | K19: =MAXIFS('01_Datos_brutos'!Q4:Q187,'01_Datos_brutos'!A4:A187,"M0") | L19: =J19-H19
A20: M0 | B20: NumeroStops | C20: =COUNTIFS('01_Datos_brutos'!A4:A187,"M0") | D20: =AVERAGEIFS('01_Datos_brutos'!V4:V187,'01_Datos_brutos'!A4:A187,"M0") | E20: =STDEV(IF('01_Datos_brutos'!A4:A187="M0",'01_Datos_brutos'!V4:V187)) | F20: =IFERROR(E20/D20,"") | G20: =MINIFS('01_Datos_brutos'!V4:V187,'01_Datos_brutos'!A4:A187,"M0") | H20: =PERCENTILE(IF('01_Datos_brutos'!A4:A187="M0",'01_Datos_brutos'!V4:V187),0.25) | I20: =PERCENTILE(IF('01_Datos_brutos'!A4:A187="M0",'01_Datos_brutos'!V4:V187),0.5) | J20: =PERCENTILE(IF('01_Datos_brutos'!A4:A187="M0",'01_Datos_brutos'!V4:V187),0.75) | K20: =MAXIFS('01_Datos_brutos'!V4:V187,'01_Datos_brutos'!A4:A187,"M0") | L20: =J20-H20
A21: M0 | B21: TiempoStop_s | C21: =COUNTIFS('01_Datos_brutos'!A4:A187,"M0") | D21: =AVERAGEIFS('01_Datos_brutos'!U4:U187,'01_Datos_brutos'!A4:A187,"M0") | E21: =STDEV(IF('01_Datos_brutos'!A4:A187="M0",'01_Datos_brutos'!U4:U187)) | F21: =IFERROR(E21/D21,"") | G21: =MINIFS('01_Datos_brutos'!U4:U187,'01_Datos_brutos'!A4:A187,"M0") | H21: =PERCENTILE(IF('01_Datos_brutos'!A4:A187="M0",'01_Datos_brutos'!U4:U187),0.25) | I21: =PERCENTILE(IF('01_Datos_brutos'!A4:A187="M0",'01_Datos_brutos'!U4:U187),0.5) | J21: =PERCENTILE(IF('01_Datos_brutos'!A4:A187="M0",'01_Datos_brutos'!U4:U187),0.75) | K21: =MAXIFS('01_Datos_brutos'!U4:U187,'01_Datos_brutos'!A4:A187,"M0") | L21: =J21-H21
A22: M0 | B22: EficienciaTrayectoria | C22: =COUNTIFS('01_Datos_brutos'!A4:A187,"M0") | D22: =AVERAGEIFS('01_Datos_brutos'!W4:W187,'01_Datos_brutos'!A4:A187,"M0") | E22: =STDEV(IF('01_Datos_brutos'!A4:A187="M0",'01_Datos_brutos'!W4:W187)) | F22: =IFERROR(E22/D22,"") | G22: =MINIFS('01_Datos_brutos'!W4:W187,'01_Datos_brutos'!A4:A187,"M0") | H22: =PERCENTILE(IF('01_Datos_brutos'!A4:A187="M0",'01_Datos_brutos'!W4:W187),0.25) | I22: =PERCENTILE(IF('01_Datos_brutos'!A4:A187="M0",'01_Datos_brutos'!W4:W187),0.5) | J22: =PERCENTILE(IF('01_Datos_brutos'!A4:A187="M0",'01_Datos_brutos'!W4:W187),0.75) | K22: =MAXIFS('01_Datos_brutos'!W4:W187,'01_Datos_brutos'!A4:A187,"M0") | L22: =J22-H22
A23: M1 | B23: DistMin_m | C23: =COUNTIFS('01_Datos_brutos'!A4:A187,"M1") | D23: =AVERAGEIFS('01_Datos_brutos'!G4:G187,'01_Datos_brutos'!A4:A187,"M1") | E23: =STDEV(IF('01_Datos_brutos'!A4:A187="M1",'01_Datos_brutos'!G4:G187)) | F23: =IFERROR(E23/D23,"") | G23: =MINIFS('01_Datos_brutos'!G4:G187,'01_Datos_brutos'!A4:A187,"M1") | H23: =PERCENTILE(IF('01_Datos_brutos'!A4:A187="M1",'01_Datos_brutos'!G4:G187),0.25) | I23: =PERCENTILE(IF('01_Datos_brutos'!A4:A187="M1",'01_Datos_brutos'!G4:G187),0.5) | J23: =PERCENTILE(IF('01_Datos_brutos'!A4:A187="M1",'01_Datos_brutos'!G4:G187),0.75) | K23: =MAXIFS('01_Datos_brutos'!G4:G187,'01_Datos_brutos'!A4:A187,"M1") | L23: =J23-H23
A24: M1 | B24: DistMedia_m | C24: =COUNTIFS('01_Datos_brutos'!A4:A187,"M1") | D24: =AVERAGEIFS('01_Datos_brutos'!H4:H187,'01_Datos_brutos'!A4:A187,"M1") | E24: =STDEV(IF('01_Datos_brutos'!A4:A187="M1",'01_Datos_brutos'!H4:H187)) | F24: =IFERROR(E24/D24,"") | G24: =MINIFS('01_Datos_brutos'!H4:H187,'01_Datos_brutos'!A4:A187,"M1") | H24: =PERCENTILE(IF('01_Datos_brutos'!A4:A187="M1",'01_Datos_brutos'!H4:H187),0.25) | I24: =PERCENTILE(IF('01_Datos_brutos'!A4:A187="M1",'01_Datos_brutos'!H4:H187),0.5) | J24: =PERCENTILE(IF('01_Datos_brutos'!A4:A187="M1",'01_Datos_brutos'!H4:H187),0.75) | K24: =MAXIFS('01_Datos_brutos'!H4:H187,'01_Datos_brutos'!A4:A187,"M1") | L24: =J24-H24
A25: M1 | B25: DistP05_m | C25: =COUNTIFS('01_Datos_brutos'!A4:A187,"M1") | D25: =AVERAGEIFS('01_Datos_brutos'!J4:J187,'01_Datos_brutos'!A4:A187,"M1") | E25: =STDEV(IF('01_Datos_brutos'!A4:A187="M1",'01_Datos_brutos'!J4:J187)) | F25: =IFERROR(E25/D25,"") | G25: =MINIFS('01_Datos_brutos'!J4:J187,'01_Datos_brutos'!A4:A187,"M1") | H25: =PERCENTILE(IF('01_Datos_brutos'!A4:A187="M1",'01_Datos_brutos'!J4:J187),0.25) | I25: =PERCENTILE(IF('01_Datos_brutos'!A4:A187="M1",'01_Datos_brutos'!J4:J187),0.5) | J25: =PERCENTILE(IF('01_Datos_brutos'!A4:A187="M1",'01_Datos_brutos'!J4:J187),0.75) | K25: =MAXIFS('01_Datos_brutos'!J4:J187,'01_Datos_brutos'!A4:A187,"M1") | L25: =J25-H25
A26: M1 | B26: TiempoPersonal_s | C26: =COUNTIFS('01_Datos_brutos'!A4:A187,"M1") | D26: =AVERAGEIFS('01_Datos_brutos'!S4:S187,'01_Datos_brutos'!A4:A187,"M1") | E26: =STDEV(IF('01_Datos_brutos'!A4:A187="M1",'01_Datos_brutos'!S4:S187)) | F26: =IFERROR(E26/D26,"") | G26: =MINIFS('01_Datos_brutos'!S4:S187,'01_Datos_brutos'!A4:A187,"M1") | H26: =PERCENTILE(IF('01_Datos_brutos'!A4:A187="M1",'01_Datos_brutos'!S4:S187),0.25) | I26: =PERCENTILE(IF('01_Datos_brutos'!A4:A187="M1",'01_Datos_brutos'!S4:S187),0.5) | J26: =PERCENTILE(IF('01_Datos_brutos'!A4:A187="M1",'01_Datos_brutos'!S4:S187),0.75) | K26: =MAXIFS('01_Datos_brutos'!S4:S187,'01_Datos_brutos'!A4:A187,"M1") | L26: =J26-H26
A27: M1 | B27: TiempoIntima_s | C27: =COUNTIFS('01_Datos_brutos'!A4:A187,"M1") | D27: =AVERAGEIFS('01_Datos_brutos'!T4:T187,'01_Datos_brutos'!A4:A187,"M1") | E27: =STDEV(IF('01_Datos_brutos'!A4:A187="M1",'01_Datos_brutos'!T4:T187)) | F27: =IFERROR(E27/D27,"") | G27: =MINIFS('01_Datos_brutos'!T4:T187,'01_Datos_brutos'!A4:A187,"M1") | H27: =PERCENTILE(IF('01_Datos_brutos'!A4:A187="M1",'01_Datos_brutos'!T4:T187),0.25) | I27: =PERCENTILE(IF('01_Datos_brutos'!A4:A187="M1",'01_Datos_brutos'!T4:T187),0.5) | J27: =PERCENTILE(IF('01_Datos_brutos'!A4:A187="M1",'01_Datos_brutos'!T4:T187),0.75) | K27: =MAXIFS('01_Datos_brutos'!T4:T187,'01_Datos_brutos'!A4:A187,"M1") | L27: =J27-H27
A28: M1 | B28: TiempoTotal_s | C28: =COUNTIFS('01_Datos_brutos'!A4:A187,"M1") | D28: =AVERAGEIFS('01_Datos_brutos'!E4:E187,'01_Datos_brutos'!A4:A187,"M1") | E28: =STDEV(IF('01_Datos_brutos'!A4:A187="M1",'01_Datos_brutos'!E4:E187)) | F28: =IFERROR(E28/D28,"") | G28: =MINIFS('01_Datos_brutos'!E4:E187,'01_Datos_brutos'!A4:A187,"M1") | H28: =PERCENTILE(IF('01_Datos_brutos'!A4:A187="M1",'01_Datos_brutos'!E4:E187),0.25) | I28: =PERCENTILE(IF('01_Datos_brutos'!A4:A187="M1",'01_Datos_brutos'!E4:E187),0.5) | J28: =PERCENTILE(IF('01_Datos_brutos'!A4:A187="M1",'01_Datos_brutos'!E4:E187),0.75) | K28: =MAXIFS('01_Datos_brutos'!E4:E187,'01_Datos_brutos'!A4:A187,"M1") | L28: =J28-H28
A29: M1 | B29: LongitudTrayectoria_m | C29: =COUNTIFS('01_Datos_brutos'!A4:A187,"M1") | D29: =AVERAGEIFS('01_Datos_brutos'!F4:F187,'01_Datos_brutos'!A4:A187,"M1") | E29: =STDEV(IF('01_Datos_brutos'!A4:A187="M1",'01_Datos_brutos'!F4:F187)) | F29: =IFERROR(E29/D29,"") | G29: =MINIFS('01_Datos_brutos'!F4:F187,'01_Datos_brutos'!A4:A187,"M1") | H29: =PERCENTILE(IF('01_Datos_brutos'!A4:A187="M1",'01_Datos_brutos'!F4:F187),0.25) | I29: =PERCENTILE(IF('01_Datos_brutos'!A4:A187="M1",'01_Datos_brutos'!F4:F187),0.5) | J29: =PERCENTILE(IF('01_Datos_brutos'!A4:A187="M1",'01_Datos_brutos'!F4:F187),0.75) | K29: =MAXIFS('01_Datos_brutos'!F4:F187,'01_Datos_brutos'!A4:A187,"M1") | L29: =J29-H29
A30: M1 | B30: VelMedia_mps | C30: =COUNTIFS('01_Datos_brutos'!A4:A187,"M1") | D30: =AVERAGEIFS('01_Datos_brutos'!L4:L187,'01_Datos_brutos'!A4:A187,"M1") | E30: =STDEV(IF('01_Datos_brutos'!A4:A187="M1",'01_Datos_brutos'!L4:L187)) | F30: =IFERROR(E30/D30,"") | G30: =MINIFS('01_Datos_brutos'!L4:L187,'01_Datos_brutos'!A4:A187,"M1") | H30: =PERCENTILE(IF('01_Datos_brutos'!A4:A187="M1",'01_Datos_brutos'!L4:L187),0.25) | I30: =PERCENTILE(IF('01_Datos_brutos'!A4:A187="M1",'01_Datos_brutos'!L4:L187),0.5) | J30: =PERCENTILE(IF('01_Datos_brutos'!A4:A187="M1",'01_Datos_brutos'!L4:L187),0.75) | K30: =MAXIFS('01_Datos_brutos'!L4:L187,'01_Datos_brutos'!A4:A187,"M1") | L30: =J30-H30
A31: M1 | B31: VelMax_mps | C31: =COUNTIFS('01_Datos_brutos'!A4:A187,"M1") | D31: =AVERAGEIFS('01_Datos_brutos'!N4:N187,'01_Datos_brutos'!A4:A187,"M1") | E31: =STDEV(IF('01_Datos_brutos'!A4:A187="M1",'01_Datos_brutos'!N4:N187)) | F31: =IFERROR(E31/D31,"") | G31: =MINIFS('01_Datos_brutos'!N4:N187,'01_Datos_brutos'!A4:A187,"M1") | H31: =PERCENTILE(IF('01_Datos_brutos'!A4:A187="M1",'01_Datos_brutos'!N4:N187),0.25) | I31: =PERCENTILE(IF('01_Datos_brutos'!A4:A187="M1",'01_Datos_brutos'!N4:N187),0.5) | J31: =PERCENTILE(IF('01_Datos_brutos'!A4:A187="M1",'01_Datos_brutos'!N4:N187),0.75) | K31: =MAXIFS('01_Datos_brutos'!N4:N187,'01_Datos_brutos'!A4:A187,"M1") | L31: =J31-H31
A32: M1 | B32: VelStd_mps | C32: =COUNTIFS('01_Datos_brutos'!A4:A187,"M1") | D32: =AVERAGEIFS('01_Datos_brutos'!O4:O187,'01_Datos_brutos'!A4:A187,"M1") | E32: =STDEV(IF('01_Datos_brutos'!A4:A187="M1",'01_Datos_brutos'!O4:O187)) | F32: =IFERROR(E32/D32,"") | G32: =MINIFS('01_Datos_brutos'!O4:O187,'01_Datos_brutos'!A4:A187,"M1") | H32: =PERCENTILE(IF('01_Datos_brutos'!A4:A187="M1",'01_Datos_brutos'!O4:O187),0.25) | I32: =PERCENTILE(IF('01_Datos_brutos'!A4:A187="M1",'01_Datos_brutos'!O4:O187),0.5) | J32: =PERCENTILE(IF('01_Datos_brutos'!A4:A187="M1",'01_Datos_brutos'!O4:O187),0.75) | K32: =MAXIFS('01_Datos_brutos'!O4:O187,'01_Datos_brutos'!A4:A187,"M1") | L32: =J32-H32
A33: M1 | B33: AccMax_mps2 | C33: =COUNTIFS('01_Datos_brutos'!A4:A187,"M1") | D33: =AVERAGEIFS('01_Datos_brutos'!P4:P187,'01_Datos_brutos'!A4:A187,"M1") | E33: =STDEV(IF('01_Datos_brutos'!A4:A187="M1",'01_Datos_brutos'!P4:P187)) | F33: =IFERROR(E33/D33,"") | G33: =MINIFS('01_Datos_brutos'!P4:P187,'01_Datos_brutos'!A4:A187,"M1") | H33: =PERCENTILE(IF('01_Datos_brutos'!A4:A187="M1",'01_Datos_brutos'!P4:P187),0.25) | I33: =PERCENTILE(IF('01_Datos_brutos'!A4:A187="M1",'01_Datos_brutos'!P4:P187),0.5) | J33: =PERCENTILE(IF('01_Datos_brutos'!A4:A187="M1",'01_Datos_brutos'!P4:P187),0.75) | K33: =MAXIFS('01_Datos_brutos'!P4:P187,'01_Datos_brutos'!A4:A187,"M1") | L33: =J33-H33
A34: M1 | B34: AccRMS_mps2 | C34: =COUNTIFS('01_Datos_brutos'!A4:A187,"M1") | D34: =AVERAGEIFS('01_Datos_brutos'!Q4:Q187,'01_Datos_brutos'!A4:A187,"M1") | E34: =STDEV(IF('01_Datos_brutos'!A4:A187="M1",'01_Datos_brutos'!Q4:Q187)) | F34: =IFERROR(E34/D34,"") | G34: =MINIFS('01_Datos_brutos'!Q4:Q187,'01_Datos_brutos'!A4:A187,"M1") | H34: =PERCENTILE(IF('01_Datos_brutos'!A4:A187="M1",'01_Datos_brutos'!Q4:Q187),0.25) | I34: =PERCENTILE(IF('01_Datos_brutos'!A4:A187="M1",'01_Datos_brutos'!Q4:Q187),0.5) | J34: =PERCENTILE(IF('01_Datos_brutos'!A4:A187="M1",'01_Datos_brutos'!Q4:Q187),0.75) | K34: =MAXIFS('01_Datos_brutos'!Q4:Q187,'01_Datos_brutos'!A4:A187,"M1") | L34: =J34-H34
A35: M1 | B35: NumeroStops | C35: =COUNTIFS('01_Datos_brutos'!A4:A187,"M1") | D35: =AVERAGEIFS('01_Datos_brutos'!V4:V187,'01_Datos_brutos'!A4:A187,"M1") | E35: =STDEV(IF('01_Datos_brutos'!A4:A187="M1",'01_Datos_brutos'!V4:V187)) | F35: =IFERROR(E35/D35,"") | G35: =MINIFS('01_Datos_brutos'!V4:V187,'01_Datos_brutos'!A4:A187,"M1") | H35: =PERCENTILE(IF('01_Datos_brutos'!A4:A187="M1",'01_Datos_brutos'!V4:V187),0.25) | I35: =PERCENTILE(IF('01_Datos_brutos'!A4:A187="M1",'01_Datos_brutos'!V4:V187),0.5) | J35: =PERCENTILE(IF('01_Datos_brutos'!A4:A187="M1",'01_Datos_brutos'!V4:V187),0.75) | K35: =MAXIFS('01_Datos_brutos'!V4:V187,'01_Datos_brutos'!A4:A187,"M1") | L35: =J35-H35
A36: M1 | B36: TiempoStop_s | C36: =COUNTIFS('01_Datos_brutos'!A4:A187,"M1") | D36: =AVERAGEIFS('01_Datos_brutos'!U4:U187,'01_Datos_brutos'!A4:A187,"M1") | E36: =STDEV(IF('01_Datos_brutos'!A4:A187="M1",'01_Datos_brutos'!U4:U187)) | F36: =IFERROR(E36/D36,"") | G36: =MINIFS('01_Datos_brutos'!U4:U187,'01_Datos_brutos'!A4:A187,"M1") | H36: =PERCENTILE(IF('01_Datos_brutos'!A4:A187="M1",'01_Datos_brutos'!U4:U187),0.25) | I36: =PERCENTILE(IF('01_Datos_brutos'!A4:A187="M1",'01_Datos_brutos'!U4:U187),0.5) | J36: =PERCENTILE(IF('01_Datos_brutos'!A4:A187="M1",'01_Datos_brutos'!U4:U187),0.75) | K36: =MAXIFS('01_Datos_brutos'!U4:U187,'01_Datos_brutos'!A4:A187,"M1") | L36: =J36-H36
A37: M1 | B37: EficienciaTrayectoria | C37: =COUNTIFS('01_Datos_brutos'!A4:A187,"M1") | D37: =AVERAGEIFS('01_Datos_brutos'!W4:W187,'01_Datos_brutos'!A4:A187,"M1") | E37: =STDEV(IF('01_Datos_brutos'!A4:A187="M1",'01_Datos_brutos'!W4:W187)) | F37: =IFERROR(E37/D37,"") | G37: =MINIFS('01_Datos_brutos'!W4:W187,'01_Datos_brutos'!A4:A187,"M1") | H37: =PERCENTILE(IF('01_Datos_brutos'!A4:A187="M1",'01_Datos_brutos'!W4:W187),0.25) | I37: =PERCENTILE(IF('01_Datos_brutos'!A4:A187="M1",'01_Datos_brutos'!W4:W187),0.5) | J37: =PERCENTILE(IF('01_Datos_brutos'!A4:A187="M1",'01_Datos_brutos'!W4:W187),0.75) | K37: =MAXIFS('01_Datos_brutos'!W4:W187,'01_Datos_brutos'!A4:A187,"M1") | L37: =J37-H37
A38: M2 | B38: DistMin_m | C38: =COUNTIFS('01_Datos_brutos'!A4:A187,"M2") | D38: =AVERAGEIFS('01_Datos_brutos'!G4:G187,'01_Datos_brutos'!A4:A187,"M2") | E38: =STDEV(IF('01_Datos_brutos'!A4:A187="M2",'01_Datos_brutos'!G4:G187)) | F38: =IFERROR(E38/D38,"") | G38: =MINIFS('01_Datos_brutos'!G4:G187,'01_Datos_brutos'!A4:A187,"M2") | H38: =PERCENTILE(IF('01_Datos_brutos'!A4:A187="M2",'01_Datos_brutos'!G4:G187),0.25) | I38: =PERCENTILE(IF('01_Datos_brutos'!A4:A187="M2",'01_Datos_brutos'!G4:G187),0.5) | J38: =PERCENTILE(IF('01_Datos_brutos'!A4:A187="M2",'01_Datos_brutos'!G4:G187),0.75) | K38: =MAXIFS('01_Datos_brutos'!G4:G187,'01_Datos_brutos'!A4:A187,"M2") | L38: =J38-H38
A39: M2 | B39: DistMedia_m | C39: =COUNTIFS('01_Datos_brutos'!A4:A187,"M2") | D39: =AVERAGEIFS('01_Datos_brutos'!H4:H187,'01_Datos_brutos'!A4:A187,"M2") | E39: =STDEV(IF('01_Datos_brutos'!A4:A187="M2",'01_Datos_brutos'!H4:H187)) | F39: =IFERROR(E39/D39,"") | G39: =MINIFS('01_Datos_brutos'!H4:H187,'01_Datos_brutos'!A4:A187,"M2") | H39: =PERCENTILE(IF('01_Datos_brutos'!A4:A187="M2",'01_Datos_brutos'!H4:H187),0.25) | I39: =PERCENTILE(IF('01_Datos_brutos'!A4:A187="M2",'01_Datos_brutos'!H4:H187),0.5) | J39: =PERCENTILE(IF('01_Datos_brutos'!A4:A187="M2",'01_Datos_brutos'!H4:H187),0.75) | K39: =MAXIFS('01_Datos_brutos'!H4:H187,'01_Datos_brutos'!A4:A187,"M2") | L39: =J39-H39
A40: M2 | B40: DistP05_m | C40: =COUNTIFS('01_Datos_brutos'!A4:A187,"M2") | D40: =AVERAGEIFS('01_Datos_brutos'!J4:J187,'01_Datos_brutos'!A4:A187,"M2") | E40: =STDEV(IF('01_Datos_brutos'!A4:A187="M2",'01_Datos_brutos'!J4:J187)) | F40: =IFERROR(E40/D40,"") | G40: =MINIFS('01_Datos_brutos'!J4:J187,'01_Datos_brutos'!A4:A187,"M2") | H40: =PERCENTILE(IF('01_Datos_brutos'!A4:A187="M2",'01_Datos_brutos'!J4:J187),0.25) | I40: =PERCENTILE(IF('01_Datos_brutos'!A4:A187="M2",'01_Datos_brutos'!J4:J187),0.5) | J40: =PERCENTILE(IF('01_Datos_brutos'!A4:A187="M2",'01_Datos_brutos'!J4:J187),0.75) | K40: =MAXIFS('01_Datos_brutos'!J4:J187,'01_Datos_brutos'!A4:A187,"M2") | L40: =J40-H40
A41: M2 | B41: TiempoPersonal_s | C41: =COUNTIFS('01_Datos_brutos'!A4:A187,"M2") | D41: =AVERAGEIFS('01_Datos_brutos'!S4:S187,'01_Datos_brutos'!A4:A187,"M2") | E41: =STDEV(IF('01_Datos_brutos'!A4:A187="M2",'01_Datos_brutos'!S4:S187)) | F41: =IFERROR(E41/D41,"") | G41: =MINIFS('01_Datos_brutos'!S4:S187,'01_Datos_brutos'!A4:A187,"M2") | H41: =PERCENTILE(IF('01_Datos_brutos'!A4:A187="M2",'01_Datos_brutos'!S4:S187),0.25) | I41: =PERCENTILE(IF('01_Datos_brutos'!A4:A187="M2",'01_Datos_brutos'!S4:S187),0.5) | J41: =PERCENTILE(IF('01_Datos_brutos'!A4:A187="M2",'01_Datos_brutos'!S4:S187),0.75) | K41: =MAXIFS('01_Datos_brutos'!S4:S187,'01_Datos_brutos'!A4:A187,"M2") | L41: =J41-H41
A42: M2 | B42: TiempoIntima_s | C42: =COUNTIFS('01_Datos_brutos'!A4:A187,"M2") | D42: =AVERAGEIFS('01_Datos_brutos'!T4:T187,'01_Datos_brutos'!A4:A187,"M2") | E42: =STDEV(IF('01_Datos_brutos'!A4:A187="M2",'01_Datos_brutos'!T4:T187)) | F42: =IFERROR(E42/D42,"") | G42: =MINIFS('01_Datos_brutos'!T4:T187,'01_Datos_brutos'!A4:A187,"M2") | H42: =PERCENTILE(IF('01_Datos_brutos'!A4:A187="M2",'01_Datos_brutos'!T4:T187),0.25) | I42: =PERCENTILE(IF('01_Datos_brutos'!A4:A187="M2",'01_Datos_brutos'!T4:T187),0.5) | J42: =PERCENTILE(IF('01_Datos_brutos'!A4:A187="M2",'01_Datos_brutos'!T4:T187),0.75) | K42: =MAXIFS('01_Datos_brutos'!T4:T187,'01_Datos_brutos'!A4:A187,"M2") | L42: =J42-H42
...

Sheet 03_Kruskal_Wallis
A1: KRUSKAL-WALLIS: RESULTADOS POR METRICA
A3: Hipótesis nula H_0: las 5 muestras provienen de la misma distribución.
A4: Estadístico H sigue chi^2(df=4) bajo H_0.
A5: Puntos críticos: chi^2(4,0.05)=9.488, chi^2(4,0.01)=13.277, chi^2(4,0.001)=18.467.
A7: Metrica | B7: H | C7: df | D7: N total | E7: p-valor | F7: Sig. | G7: Sig. 0.05 | H7: Sig. 0.001
A8: DistMin_m | B8: 115.29871 | C8: 4 | D8: 184 | E8: 5.3858358e-24 | F8: *** | G8: =IF(B8>9.488,"SI","NO") | H8: =IF(B8>18.467,"SI","NO")
A9: DistMedia_m | B9: 9.6843442 | C9: 4 | D9: 184 | E9: 0.046094142 | F9: * | G9: =IF(B9>9.488,"SI","NO") | H9: =IF(B9>18.467,"SI","NO")
A10: DistP05_m | B10: 90.536616 | C10: 4 | D10: 184 | E10: 1.0127186e-18 | F10: *** | G10: =IF(B10>9.488,"SI","NO") | H10: =IF(B10>18.467,"SI","NO")
A11: TiempoPersonal_s | B11: 43.121475 | C11: 4 | D11: 184 | E11: 9.7324374e-09 | F11: *** | G11: =IF(B11>9.488,"SI","NO") | H11: =IF(B11>18.467,"SI","NO")
A12: TiempoIntima_s | B12: 0.23351351 | C12: 4 | D12: 184 | E12: 0.12376776 | F12: ns | G12: =IF(B12>9.488,"SI","NO") | H12: =IF(B12>18.467,"SI","NO")
A13: TiempoTotal_s | B13: 36.339512 | C13: 4 | D13: 184 | E13: 2.4637231e-07 | F13: *** | G13: =IF(B13>9.488,"SI","NO") | H13: =IF(B13>18.467,"SI","NO")
A14: LongitudTrayectoria_m | B14: 47.322499 | C14: 4 | D14: 184 | E14: 1.3063662e-09 | F14: *** | G14: =IF(B14>9.488,"SI","NO") | H14: =IF(B14>18.467,"SI","NO")
A15: VelMedia_mps | B15: 95.641562 | C15: 4 | D15: 184 | E15: 8.3230747e-20 | F15: *** | G15: =IF(B15>9.488,"SI","NO") | H15: =IF(B15>18.467,"SI","NO")
A16: VelMax_mps | B16: 12.870256 | C16: 4 | D16: 184 | E16: 0.011718977 | F16: * | G16: =IF(B16>9.488,"SI","NO") | H16: =IF(B16>18.467,"SI","NO")
A17: VelStd_mps | B17: 164.97099 | C17: 4 | D17: 184 | E17: 1.2549195e-34 | F17: *** | G17: =IF(B17>9.488,"SI","NO") | H17: =IF(B17>18.467,"SI","NO")
A18: AccMax_mps2 | B18: 3.9619147 | C18: 4 | D18: 184 | E18: 0.41118468 | F18: ns | G18: =IF(B18>9.488,"SI","NO") | H18: =IF(B18>18.467,"SI","NO")
A19: AccRMS_mps2 | B19: 14.139406 | C19: 4 | D19: 184 | E19: 0.0068631672 | F19: ** | G19: =IF(B19>9.488,"SI","NO") | H19: =IF(B19>18.467,"SI","NO")
... A22: EficienciaTrayectoria | B22: 96.320634 | C22: 4 | D22: 184 | E22: 5.968357e-20 | F22: *** | G22: =IF(B22>9.488,"SI","NO") | H22: =IF(B22>18.467,"SI","NO")
A25: Sumas de rangos por método (DistMin_m)
A26: Método | B26: n | C26: R_j | D26: Rank medio
A27: M0 | B27: 40 | C27: 1114 | D27: =C27/B27
A28: M1 | B28: 32 | C28: 2729.5 | D28: =C28/B28
A29: M2 | B29: 32 | C29: 2667 | D29: =C29/B29
A30: M3 | B30: 40 | C30: 6087.5 | D30: =C30/B30
A31: M4 | B31: 40 | C31: 4422 | D31: =C31/B31

Sheet 04_Mann_Whitney
A1: MANN-WHITNEY U + HOLM-BONFERRONI + CLIFF DELTA
A3: Convención Cliff: delta(A,B) = P(X_A>X_B) - P(X_A<X_B). Positivo = A tiende a ser mayor que B.
A5: Métrica: DistMin_m
A6: Comp. | B6: med A | C6: med B | D6: U | E6: p_raw | F6: rank Holm | G6: mult. | H6: p_Holm | I6: Cliff δ | J6: Magnitud | K6: Sig.
A7: M0 vs M3 | B7: 0.5555 | C7: 0.9483 | D7: 30 | E7: 1.3158543e-13 | F7: 1 | G7: 10 | H7: =MIN(1, E7*G7) | I7: -0.9625 | J7: large | K7: =IF(H7<0.001,"***",IF(H7<0.01,"**",IF(H7<0.05,"*","ns")))
A8: M0 vs M4 | B8: 0.5555 | C8: 0.8076 | D8: 60 | E8: 1.1123161e-12 | F8: 2 | G8: 9 | H8: =MIN(1, E8*G8) | I8: -0.925 | J8: large | K8: =IF(H8<0.001,"***",IF(H8<0.01,"**",IF(H8<0.05,"*","ns")))
A9: M0 vs M1 | B9: 0.5555 | C9: 0.7576 | D9: 96 | E9: 7.3116944e-10 | F9: 3 | G9: 8 | H9: =MIN(1, E9*G9) | I9: -0.85 | J9: large | K9: =IF(H9<0.001,"***",IF(H9<0.01,"**",IF(H9<0.05,"*","ns")))
A10: M1 vs M3 | B10: 0.7576 | C10: 0.9483 | D10: 98 | E10: 8.4318711e-10 | F10: 4 | G10: 7 | H10: =MIN(1, E10*G10) | I10: -0.846875 | J10: large | K10: =IF(H10<0.001,"***",IF(H10<0.01,"**",IF(H10<0.05,"*","ns")))
A11: M2 vs M3 | B11: 0.7353 | C11: 0.9483 | D11: 102 | E11: 1.1200068e-09 | F11: 5 | G11: 6 | H11: =MIN(1, E11*G11) | I11: -0.840625 | J11: large | K11: =IF(H11<0.001,"***",IF(H11<0.01,"**",IF(H11<0.05,"*","ns")))
A12: M0 vs M2 | B12: 0.5555 | C12: 0.7353 | D12: 108 | E12: 1.7094792e-09 | F12: 6 | G12: 5 | H12: =MIN(1, E12*G12) | I12: -0.83125 | J12: large | K12: =IF(H12<0.001,"***",IF(H12<0.01,"**",IF(H12<0.05,"*","ns")))
A13: M3 vs M4 | B13: 0.9483 | C13: 0.8076 | D13: 1337.5 | E13: 2.3744213e-07 | F13: 7 | G13: 4 | H13: =MIN(1, E13*G13) | I13: 0.671875 | J13: large | K13: =IF(H13<0.001,"***",IF(H13<0.01,"**",IF(H13<0.05,"*","ns")))
A14: M2 vs M4 | B14: 0.7353 | C14: 0.8076 | D14: 373 | E14: 0.0025267041 | F14: 8 | G14: 3 | H14: =MIN(1, E14*G14) | I14: -0.4171875 | J14: medium | K14: =IF(H14<0.001,"***",IF(H14<0.01,"**",IF(H14<0.05,"*","ns")))
A15: M1 vs M4 | B15: 0.7576 | C15: 0.8076 | D15: 387.5 | E15: 0.0042928145 | F15: 9 | G15: 2 | H15: =MIN(1, E15*G15) | I15: -0.39453125 | J15: medium | K15: =IF(H15<0.001,"***",IF(H15<0.01,"**",IF(H15<0.05,"*","ns")))
A16: M1 vs M2 | B16: 0.7576 | C16: 0.7353 | D16: 532 | E16: 0.79343903 | F16: 10 | G16: 1 | H16: =MIN(1, E16*G16) | I16: 0.0390625 | J16: negligible | K16: =IF(H16<0.001,"***",IF(H16<0.01,"**",IF(H16<0.05,"*","ns")))
A18: Métrica: TiempoPersonal_s
A19: Comp. | B19: med A | C19: med B | D19: U | E19: p_raw | F19: rank Holm | G19: mult. | H19: p_Holm | I19: Cliff δ | J19: Magnitud | K19: Sig.
A20: M1 vs M3 | B20: 16.37395 | C20: 7.04915 | D20: 1104 | E20: 1.4710555e-07 | F20: 1 | G20: 10 | H20: =MIN(1, E20*G20) | I20: 0.725 | J20: large | K20: =IF(H20<0.001,"***",IF(H20<0.01,"**",IF(H20<0.05,"*","ns")))
A21: M0 vs M3 | B21: 28.1146 | C21: 7.04915 | D21: 1292 | E21: 2.2254768e-06 | F21: 2 | G21: 9 | H21: =MIN(1, E21*G21) | I21: 0.615 | J21: large | K21: =IF(H21<0.001,"***",IF(H21<0.01,"**",IF(H21<0.05,"*","ns")))
A22: M0 vs M4 | B22: 28.1146 | C22: 7.0213 | D22: 1171 | E22: 0.00036363594 | F22: 3 | G22: 8 | H22: =MIN(1, E22*G22) | I22: 0.46375 | J22: medium | K22: =IF(H22<0.001,"***",IF(H22<0.01,"**",IF(H22<0.05,"*","ns")))
A23: M1 vs M4 | B23: 16.37395 | C23: 7.0213 | D23: 951 | E23: 0.00043357327 | F23: 4 | G23: 7 | H23: =MIN(1, E23*G23) | I23: 0.4859375 | J23: large | K23: =IF(H23<0.001,"***",IF(H23<0.01,"**",IF(H23<0.05,"*","ns")))
A24: M1 vs M2 | B24: 16.37395 | C24: 10.82455 | D24: 759 | E24: 0.00093364846 | F24: 5 | G24: 6 | H24: =MIN(1, E24*G24) | I24: 0.48242188 | J24: large | K24: =IF(H24<0.001,"***",IF(H24<0.01,"**",IF(H24<0.05,"*","ns")))
A25: M2 vs M3 | B25: 10.82455 | C25: 7.04915 | D25: 916 | E25: 0.0017828725 | F25: 6 | G25: 5 | H25: =MIN(1, E25*G25) | I25: 0.43125 | J25: medium | K25: =IF(H25<0.001,"***",IF(H25<0.01,"**",IF(H25<0.05,"*","ns")))
A26: M0 vs M2 | B26: 28.1146 | C26: 10.82455 | D26: 873 | E26: 0.0084187608 | F26: 7 | G26: 4 | H26: =MIN(1, E26*G26) | I26: 0.3640625 | J26: medium | K26: =IF(H26<0.001,"***",IF(H26<0.01,"**",IF(H26<0.05,"*","ns")))
A27: M3 vs M4 | B27: 7.04915 | C27: 7.0213 | D27: 610 | E27: 0.067966275 | F27: 8 | G27: 3 | H27: =MIN(1, E27*G27) | I27: -0.2375 | J27: small | K27: =IF(H27<0.001,"***",IF(H27<0.01,"**",IF(H27<0.05,"*","ns")))
A28: M2 vs M4 | B28: 10.82455 | C28: 7.0213 | D28: 754 | E28: 0.19835771 | F28: 9 | G28: 2 | H28: =MIN(1, E28*G28) | I28: 0.178125 | J28: small | K28: =IF(H28<0.001,"***",IF(H28<0.01,"**",IF(H28<0.05,"*","ns")))
A29: M0 vs M1 | B29: 28.1146 | C29: 16.37395 | D29: 744 | E29: 0.24083204 | F29: 10 | G29: 1 | H29: =MIN(1, E29*G29) | I29: 0.1625 | J29: small | K29: =IF(H29<0.001,"***",IF(H29<0.01,"**",IF(H29<0.05,"*","ns")))
A31: Métrica: NumeroStops
A32: Comp. | B32: med A | C32: med B | D32: U | E32: p_raw | F32: rank Holm | G32: mult. | H32: p_Holm | I32: Cliff δ | J32: Magnitud | K32: Sig.
A33: M2 vs M3 | B33: 3 | C33: 0 | D33: 1279 | E33: 2.3813218e-15 | F33: 1 | G33: 10 | H33: =MIN(1, E33*G33) | I33: 0.9984375 | J33: large | K33: =IF(H33<0.001,"***",IF(H33<0.01,"**",IF(H33<0.05,"*","ns")))
A34: M1 vs M3 | B34: 3 | C34: 0 | D34: 1279.5 | E34: 2.3969096e-15 | F34: 2 | G34: 9 | H34: =MIN(1, E34*G34) | I34: 0.99921875 | J34: large | K34: =IF(H34<0.001,"***",IF(H34<0.01,"**",IF(H34<0.05,"*","ns")))
A35: M0 vs M1 | B35: 0 | C35: 3 | D35: 4 | E35: 3.7760233e-14 | F35: 3 | G35: 8 | H35: =MIN(1, E35*G35) | I35: -0.99375 | J35: large | K35: =IF(H35<0.001,"***",IF(H35<0.01,"**",IF(H35<0.05,"*","ns")))
A36: M1 vs M4 | B36: 3 | C36: 0 | D36: 1276 | E36: 3.7760233e-14 | F36: 4 | G36: 7 | H36: =MIN(1, E36*G36) | I36: 0.99375 | J36: large | K36: =IF(H36<0.001,"***",IF(H36<0.01,"**",IF(H36<0.05,"*","ns")))
A37: M0 vs M2 | B37: 0 | C37: 3 | D37: 8 | E37: 5.0813938e-14 | F37: 5 | G37: 6 | H37: =MIN(1, E37*G37) | I37: -0.9875 | J37: large | K37: =IF(H37<0.001,"***",IF(H37<0.01,"**",IF(H37<0.05,"*","ns")))
A38: M2 vs M4 | B38: 3 | C38: 0 | D38: 1272 | E38: 5.0813938e-14 | F38: 6 | G38: 5 | H38: =MIN(1, E38*G38) | I38: 0.9875 | J38: large | K38: =IF(H38<0.001,"***",IF(H38<0.01,"**",IF(H38<0.05,"*","ns")))
A39: M0 vs M3 | B39: 0 | C39: 0 | D39: 940 | E39: 0.014187114 | F39: 7 | G39: 4 | H39: =MIN(1, E39*G39) | I39: 0.175 | J39: small | K39: =IF(H39<0.001,"***",IF(H39<0.01,"**",IF(H39<0.05,"*","ns")))
A40: M3 vs M4 | B40: 0 | C40: 0 | D40: 660 | E40: 0.014187114 | F40: 8 | G40: 3 | H40: =MIN(1, E40*G40) | I40: -0.175 | J40: small | K40: =IF(H40<0.001,"***",IF(H40<0.01,"**",IF(H40<0.05,"*","ns")))
A41: M1 vs M2 | B41: 3 | C41: 3 | D41: 605 | E41: 0.20057373 | F41: 9 | G41: 2 | H41: =MIN(1, E41*G41) | I41: 0.18164062 | J41: small | K41: =IF(H41<0.001,"***",IF(H41<0.01,"**",IF(H41<0.05,"*","ns")))
A42: M0 vs M4 | B42: 0 | C42: 0 | D42: 800 | E42: 1 | F42: 10 | G42: 1 | H42: =MIN(1, E42*G42) | I42: 0 | J42: negligible | K42: =IF(H42<0.001,"***",IF(H42<0.01,"**",IF(H42<0.05,"*","ns")))
A44: Métrica: VelStd_mps
A45: Comp. | B45: med A | C45: med B | D45: U | E45: p_raw | F45: rank Holm | G45: mult. | H45: p_Holm | I45: Cliff δ | J45: Magnitud | K45: Sig.
...

Sheet 05_Fisher_Chi
A1: FISHER EXACTO + CHI-CUADRADO + CRAMER'S V
A3: Tabla 5x2 de éxitos/fallos por método (200 corridas planificadas)
A5: Método | B5: Éxitos (O) | C5: Fallos (O) | D5: Total fila R_i | E5: Esperado éxito E | F5: Esperado fallo E | G5: (O-E)²/E éxito | H5: (O-E)²/E fallo | I5: Suma fila
A6: M0 | B6: 40 | C6: 0 | D6: =B6+C6 | E6: =$D6*B$11/$D$11 | F6: =$D6*C$11/$D$11 | G6: =(B6-E6)^2/E6 | H6: =(C6-F6)^2/F6 | I6: =G6+H6
A7: M1 | B7: 32 | C7: 8 | D7: =B7+C7 | E7: =$D7*B$11/$D$11 | F7: =$D7*C$11/$D$11 | G7: =(B7-E7)^2/E7 | H7: =(C7-F7)^2/F7 | I7: =G7+H7
A8: M2 | B8: 32 | C8: 8 | D8: =B8+C8 | E8: =$D8*B$11/$D$11 | F8: =$D8*C$11/$D$11 | G8: =(B8-E8)^2/E8 | H8: =(C8-F8)^2/F8 | I8: =G8+H8
A9: M3 | B9: 40 | C9: 0 | D9: =B9+C9 | E9: =$D9*B$11/$D$11 | F9: =$D9*C$11/$D$11 | G9: =(B9-E9)^2/E9 | H9: =(C9-F9)^2/F9 | I9: =G9+H9
A10: M4 | B10: 40 | C10: 0 | D10: =B10+C10 | E10: =$D10*B$11/$D$11 | F10: =$D10*C$11/$D$11 | G10: =(B10-E10)^2/E10 | H10: =(C10-F10)^2/F10 | I10: =G10+H10
A11: TOTAL | B11: =SUM(B6:B10) | C11: =SUM(C6:C10) | D11: =B11+C11 | I11: =SUM(I6:I10)
A13: Estadístico chi^2: | B13: =I11
A14: Grados de libertad: | B14: 4
A15: p-valor (CHISQ.DIST.RT): | B15: =CHISQ.DIST.RT(B13,B14)
A16: Cramér's V: | B16: =SQRT(B13/D11/MIN(4,1))
A18: Fisher exacto: M4 vs M1 y M4 vs M2 en E4
A19: Comparación | B19: Éxitos A | C19: Éxitos B | D19: p Fisher | E19: Sig.
A20: M4 vs M1 | B20: 2 | C20: 10 | D20: 0.00071445582 | E20: ***
A21: M4 vs M2 | B21: 2 | C21: 10 | D21: 0.00071445582 | E21: ***
A22: M3 vs M1 | B22: 2 | C22: 10 | D22: 0.00071445582 | E22: ***
A23: M3 vs M2 | B23: 2 | C23: 10 | D23: 0.00071445582 | E23: ***
A24: M0 vs M1 | B24: 10 | C24: 2 | D24: 0.00071445582 | E24: ***
A25: M0 vs M2 | B25: 10 | C25: 2 | D25: 0.00071445582 | E25: ***

Sheet 06_TOPSIS_A_sin_pen
A1: TOPSIS A: SIN PENALIZACION DE FALLOS
A3: Pasos del algoritmo TOPSIS:
A4: 1) Matriz de decisión X (input - azul)
A5: 2) Normalización vectorial: x_tilde_ij = x_ij / sqrt(sum_k x_kj^2) (formulas - negro)
A6: 3) Matriz ponderada V = w_j * x_tilde_ij (formulas)
A7: 4-5) Soluciones ideales A+ y A-
A8: 6-7) Distancias D+, D- (euclidiana)
A9: 8) CC = D-/(D+ + D-)
A11: Pesos w_j: | B11: DistMin | C11: T_personal | D11: T_mision | E11: N_stop | F11: sigma_v | G11: a_max | H11: eta_s
A12: Valor w_j | B12: 0.2 | C12: 0.15 | D12: 0.1 | E12: 0.15 | F12: 0.15 | G12: 0.1 | H12: 0.15
A13: Tipo | B13: benefit | C13: cost | D13: cost | E13: cost | F13: cost | G13: cost | H13: benefit
A14: Suma w_j (debe ser 1.0): | B14: =SUM(B12:H12)
A16: MATRIZ DE DECISION X
A17: Alt. | B17: DistMin | C17: T_personal | D17: T_mision | E17: N_stop | F17: sigma_v | G17: a_max | H17: eta_s
A18: M0 | B18: 0.56275 | C18: 25.365243 | D18: 93.630633 | E18: 0.2 | F18: 0.066285825 | G18: 12.430272 | H18: 1
A19: M1 | B19: 0.75042813 | C19: 20.322525 | D19: 107.923 | E19: 9.90625 | F19: 0.37831588 | G19: 11.275328 | H19: 0.8
A20: M2 | B20: 0.74530937 | C20: 12.428241 | D20: 109.32678 | E20: 3.21875 | F20: 0.41006278 | G20: 11.010691 | H20: 0.8
A21: M3 | B21: 1.0037675 | C21: 7.574015 | D21: 115.04312 | E21: 0.025 | F21: 0.24278337 | G21: 9.370985 | H21: 1
A22: M4 | B22: 0.8458825 | C22: 11.72021 | D22: 110.60209 | E22: 0.2 | F22: 0.1951916 | G22: 10.283765 | H22: 1
A24: Sum sq columna: | B24: =SUMSQ(B18:B22) | C24: =SUMSQ(C18:C22) | D24: =SUMSQ(D18:D22) | E24: =SUMSQ(E18:E22) | F24: =SUMSQ(F18:F22) | G24: =SUMSQ(G18:G22) | H24: =SUMSQ(H18:H22)
A25: Norma sqrt: | B25: =SQRT(B24) | C25: =SQRT(C24) | D25: =SQRT(D24) | E25: =SQRT(E24) | F25: =SQRT(F24) | G25: =SQRT(G24) | H25: =SQRT(H24)
A27: MATRIZ NORMALIZADA x_tilde
A28: Alt. | B28: DistMin | C28: T_personal | D28: T_mision | E28: N_stop | F28: sigma_v | G28: a_max | H28: eta_s
A29: M0 | B29: =B18/B25 | C29: =C18/C25 | D29: =D18/D25 | E29: =E18/E25 | F29: =F18/F25 | G29: =G18/G25 | H29: =H18/H25
A30: M1 | B30: =B19/B25 | C30: =C19/C25 | D30: =D19/D25 | E30: =E19/E25 | F30: =F19/F25 | G30: =G19/G25 | H30: =H19/H25
A31: M2 | B31: =B20/B25 | C31: =C20/C25 | D31: =D20/D25 | E31: =E20/E25 | F31: =F20/F25 | G31: =G20/G25 | H31: =H20/H25
A32: M3 | B32: =B21/B25 | C32: =C21/C25 | D32: =D21/D25 | E32: =E21/E25 | F32: =F21/F25 | G32: =G21/G25 | H32: =H21/H25
A33: M4 | B33: =B22/B25 | C33: =C22/C25 | D33: =D22/D25 | E33: =E22/E25 | F33: =F22/F25 | G33: =G22/G25 | H33: =H22/H25
A35: MATRIZ PONDERADA V = w_j * x_tilde_ij
A36: Alt. | B36: DistMin | C36: T_personal | D36: T_mision | E36: N_stop | F36: sigma_v | G36: a_max | H36: eta_s
A37: M0 | B37: =B$12*B29 | C37: =C$12*C29 | D37: =D$12*D29 | E37: =E$12*E29 | F37: =F$12*F29 | G37: =G$12*G29 | H37: =H$12*H29
A38: M1 | B38: =B$12*B30 | C38: =C$12*C30 | D38: =D$12*D30 | E38: =E$12*E30 | F38: =F$12*F30 | G38: =G$12*G30 | H38: =H$12*H30
A39: M2 | B39: =B$12*B31 | C39: =C$12*C31 | D39: =D$12*D31 | E39: =E$12*E31 | F39: =F$12*F31 | G39: =G$12*G31 | H39: =H$12*H31
A40: M3 | B40: =B$12*B32 | C40: =C$12*C32 | D40: =D$12*D32 | E40: =E$12*E32 | F40: =F$12*F32 | G40: =G$12*G32 | H40: =H$12*H32
A41: M4 | B41: =B$12*B33 | C41: =C$12*C33 | D41: =D$12*D33 | E41: =E$12*E33 | F41: =F$12*F33 | G41: =G$12*G33 | H41: =H$12*H33
A43: A+ (ideal positivo): | B43: =MAX(B37:B41) | C43: =MIN(C37:C41) | D43: =MIN(D37:D41) | E43: =MIN(E37:E41) | F43: =MIN(F37:F41) | G43: =MIN(G37:G41) | H43: =MAX(H37:H41)
A44: A- (ideal negativo): | B44: =MIN(B37:B41) | C44: =MAX(C37:C41) | D44: =MAX(D37:D41) | E44: =MAX(E37:E41) | F44: =MAX(F37:F41) | G44: =MAX(G37:G41) | H44: =MIN(H37:H41)
A46: DISTANCIAS Y CLOSENESS COEFFICIENT
A47: Alt. | B47: D+ | C47: D- | D47: CC | E47: Rank
A48: M0 | B48: =SQRT(SUMXMY2(B37:H37,$B$43:$H$43)) | C48: =SQRT(SUMXMY2(B37:H37,$B$44:$H$44)) | D48: =C48/(B48+C48) | E48: =RANK(D48,$D$48:$D$52)
...

Sheet 07_TOPSIS_B_con_pen
A1: TOPSIS B: CON PENALIZACION DE FALLOS
A3: Pasos del algoritmo TOPSIS:
A4: 1) Matriz de decisión X (input - azul)
A5: 2) Normalización vectorial: x_tilde_ij = x_ij / sqrt(sum_k x_kj^2) (formulas - negro)
A6: 3) Matriz ponderada V = w_j * x_tilde_ij (formulas)
A7: 4-5) Soluciones ideales A+ y A-
A8: 6-7) Distancias D+, D- (euclidiana)
A9: 8) CC = D-/(D+ + D-)
A11: Pesos w_j: | B11: DistMin | C11: T_personal | D11: T_mision | E11: N_stop | F11: sigma_v | G11: a_max | H11: eta_s
A12: Valor w_j | B12: 0.2 | C12: 0.15 | D12: 0.1 | E12: 0.15 | F12: 0.15 | G12: 0.1 | H12: 0.15
A13: Tipo | B13: benefit | C13: cost | D13: cost | E13: cost | F13: cost | G13: cost | H13: benefit
A14: Suma w_j (debe ser 1.0): | B14: =SUM(B12:H12)
A16: MATRIZ DE DECISION X
A17: Alt. | B17: DistMin | C17: T_personal | D17: T_mision | E17: N_stop | F17: sigma_v | G17: a_max | H17: eta_s
A18: M0 | B18: 0.56275 | C18: 25.365243 | D18: 93.630633 | E18: 0.2 | F18: 0.066285825 | G18: 12.430272 | H18: 1
A19: M1 | B19: 0.6708825 | C19: 31.61744 | D19: 122.3384 | E19: 19.125 | F19: 0.4029167 | G19: 15.217242 | H19: 0.8
A20: M2 | B20: 0.6667875 | C20: 25.302013 | D20: 123.46143 | E20: 13.775 | F20: 0.42831422 | G20: 15.005532 | H20: 0.8
A21: M3 | B21: 1.0037675 | C21: 7.574015 | D21: 115.04312 | E21: 0.025 | F21: 0.24278337 | G21: 9.370985 | H21: 1
A22: M4 | B22: 0.8458825 | C22: 11.72021 | D22: 110.60209 | E22: 0.2 | F22: 0.1951916 | G22: 10.283765 | H22: 1
A24: Sum sq columna: | B24: =SUMSQ(B18:B22) | C24: =SUMSQ(C18:C22) | D24: =SUMSQ(D18:D22) | E24: =SUMSQ(E18:E22) | F24: =SUMSQ(F18:F22) | G24: =SUMSQ(G18:G22) | H24: =SUMSQ(H18:H22)
A25: Norma sqrt: | B25: =SQRT(B24) | C25: =SQRT(C24) | D25: =SQRT(D24) | E25: =SQRT(E24) | F25: =SQRT(F24) | G25: =SQRT(G24) | H25: =SQRT(H24)
A27: MATRIZ NORMALIZADA x_tilde
A28: Alt. | B28: DistMin | C28: T_personal | D28: T_mision | E28: N_stop | F28: sigma_v | G28: a_max | H28: eta_s
A29: M0 | B29: =B18/B25 | C29: =C18/C25 | D29: =D18/D25 | E29: =E18/E25 | F29: =F18/F25 | G29: =G18/G25 | H29: =H18/H25
A30: M1 | B30: =B19/B25 | C30: =C19/C25 | D30: =D19/D25 | E30: =E19/E25 | F30: =F19/F25 | G30: =G19/G25 | H30: =H19/H25
A31: M2 | B31: =B20/B25 | C31: =C20/C25 | D31: =D20/D25 | E31: =E20/E25 | F31: =F20/F25 | G31: =G20/G25 | H31: =H20/H25
A32: M3 | B32: =B21/B25 | C32: =C21/C25 | D32: =D21/D25 | E32: =E21/E25 | F32: =F21/F25 | G32: =G21/G25 | H32: =H21/H25
A33: M4 | B33: =B22/B25 | C33: =C22/C25 | D33: =D22/D25 | E33: =E22/E25 | F33: =F22/F25 | G33: =G22/G25 | H33: =H22/H25
A35: MATRIZ PONDERADA V = w_j * x_tilde_ij
A36: Alt. | B36: DistMin | C36: T_personal | D36: T_mision | E36: N_stop | F36: sigma_v | G36: a_max | H36: eta_s
A37: M0 | B37: =B$12*B29 | C37: =C$12*C29 | D37: =D$12*D29 | E37: =E$12*E29 | F37: =F$12*F29 | G37: =G$12*G29 | H37: =H$12*H29
A38: M1 | B38: =B$12*B30 | C38: =C$12*C30 | D38: =D$12*D30 | E38: =E$12*E30 | F38: =F$12*F30 | G38: =G$12*G30 | H38: =H$12*H30
A39: M2 | B39: =B$12*B31 | C39: =C$12*C31 | D39: =D$12*D31 | E39: =E$12*E31 | F39: =F$12*F31 | G39: =G$12*G31 | H39: =H$12*H31
A40: M3 | B40: =B$12*B32 | C40: =C$12*C32 | D40: =D$12*D32 | E40: =E$12*E32 | F40: =F$12*F32 | G40: =G$12*G32 | H40: =H$12*H32
A41: M4 | B41: =B$12*B33 | C41: =C$12*C33 | D41: =D$12*D33 | E41: =E$12*E33 | F41: =F$12*F33 | G41: =G$12*G33 | H41: =H$12*H33
A43: A+ (ideal positivo): | B43: =MAX(B37:B41) | C43: =MIN(C37:C41) | D43: =MIN(D37:D41) | E43: =MIN(E37:E41) | F43: =MIN(F37:F41) | G43: =MIN(G37:G41) | H43: =MAX(H37:H41)
A44: A- (ideal negativo): | B44: =MIN(B37:B41) | C44: =MAX(C37:C41) | D44: =MAX(D37:D41) | E44: =MAX(E37:E41) | F44: =MAX(F37:F41) | G44: =MAX(G37:G41) | H44: =MIN(H37:H41)
A46: DISTANCIAS Y CLOSENESS COEFFICIENT
A47: Alt. | B47: D+ | C47: D- | D47: CC | E47: Rank
A48: M0 | B48: =SQRT(SUMXMY2(B37:H37,$B$43:$H$43)) | C48: =SQRT(SUMXMY2(B37:H37,$B$44:$H$44)) | D48: =C48/(B48+C48) | E48: =RANK(D48,$D$48:$D$52)
...

Sheet 08_Monte_Carlo
A1: MONTE CARLO: SENSIBILIDAD DE PESOS DEL TOPSIS
A3: Procedimiento: w'_j = w_j(1+ε_j), ε_j ~ U(-eps_max, +eps_max), renormalizar.
A4: 1000 muestras por configuración. Semilla = 42.
A5: Resultados precomputados en Python (no recalculables por fórmula porque requiere generación de aleatorios).
A7: eps=±10%, sin pen.
A8: Método | B8: Rank #1 % | C8: Top-2 % | D8: Mean rank | E8: SD rank | F8: Mean CC | G8: SD CC
A9: M0 | B9: 0 | C9: 0 | D9: 3 | E9: 0 | F9: 0.64799785 | G9: 0.014657988
A10: M1 | B10: 0 | C10: 0 | D10: 5 | E10: 0 | F10: 0.15240152 | G10: 0.0069754644
A11: M2 | B11: 0 | C11: 0 | D11: 4 | E11: 0 | F11: 0.52549415 | G11: 0.012385514
A12: M3 | B12: 0.49 | C12: 1 | D12: 1.51 | E12: 0.49989999 | F12: 0.80304718 | G12: 0.010539595
A13: M4 | B13: 0.51 | C13: 1 | D13: 1.49 | E13: 0.49989999 | F13: 0.80331774 | G13: 0.0083801602
A15: eps=±10%, con pen.
A16: Método | B16: Rank #1 % | C16: Top-2 % | D16: Mean rank | E16: SD rank | F16: Mean CC | G16: SD CC
A17: M0 | B17: 0 | C17: 0 | D17: 3 | E17: 0 | F17: 0.66263561 | G17: 0.012784129
A18: M1 | B18: 0 | C18: 0 | D18: 5 | E18: 0 | F18: 0.076484451 | G18: 0.0040016534
A19: M2 | B19: 0 | C19: 0 | D19: 4 | E19: 0 | F19: 0.22681403 | G19: 0.0046456371
A20: M3 | B20: 0.219 | C20: 1 | D20: 1.781 | E20: 0.41356862 | F20: 0.79670152 | G20: 0.010291791
A21: M4 | B21: 0.781 | C21: 1 | D21: 1.219 | E21: 0.41356862 | F21: 0.80086025 | G21: 0.0076057326
A23: eps=±20%, sin pen.
A24: Método | B24: Rank #1 % | C24: Top-2 % | D24: Mean rank | E24: SD rank | F24: Mean CC | G24: SD CC
A25: M0 | B25: 0 | C25: 0 | D25: 3 | E25: 0 | F25: 0.64885258 | G25: 0.027453468
A26: M1 | B26: 0 | C26: 0 | D26: 5 | E26: 0 | F26: 0.15226391 | G26: 0.013184201
A27: M2 | B27: 0 | C27: 0 | D27: 4 | E27: 0 | F27: 0.52519373 | G27: 0.024615278
A28: M3 | B28: 0.488 | C28: 1 | D28: 1.512 | E28: 0.49985598 | F28: 0.80309941 | G28: 0.02101594
A29: M4 | B29: 0.512 | C29: 1 | D29: 1.488 | E29: 0.49985598 | F29: 0.80306114 | G29: 0.01617728
A31: eps=±20%, con pen.
A32: Método | B32: Rank #1 % | C32: Top-2 % | D32: Mean rank | E32: SD rank | F32: Mean CC | G32: SD CC
A33: M0 | B33: 0 | C33: 0 | D33: 3 | E33: 0 | F33: 0.66205741 | G33: 0.025278327
A34: M1 | B34: 0 | C34: 0 | D34: 5 | E34: 0 | F34: 0.076480812 | G34: 0.0076547111
A35: M2 | B35: 0 | C35: 0 | D35: 4 | E35: 0 | F35: 0.22671075 | G35: 0.0092896289
A36: M3 | B36: 0.358 | C36: 1 | D36: 1.642 | E36: 0.47941214 | F36: 0.79735114 | G36: 0.020524658
A37: M4 | B37: 0.642 | C37: 1 | D37: 1.358 | E37: 0.47941214 | F37: 0.80074985 | G37: 0.015207464
